Workbook

Sheet Σύνοψη
A1: Ανεργία στη Δυτική Μακεδονία · τι, γιατί, τι σημαίνει, τι κάνουμε τώρα
A2: Ερώτημα: πόσο μεγάλο είναι το πρόβλημα, τι το εξηγεί με τα διαθέσιμα δεδομένα, και τι πρέπει να μετρηθεί πριν από οποιαδήποτε επένδυση. Κάθε αριθμός είναι τύπος.
A3: Α/Α | B3: Εύρημα | C3: Βασικός αριθμός | D3: Πού υπολογίζεται
A4: 1 · ΤΙ έγινε | B4: Περιγραφή με νούμερα
A5: 1.1 | B5: ="Το 2025 η ανεργία στη ΔΜ ήταν "&FIXED(Ανάλυση!F6,1,TRUE())&"% έναντι "&FIXED(Ανάλυση!F7,1,TRUE())&"% στην Ελλάδα και "&FIXED(Ανάλυση!F8,1,TRUE())&"% στην ΕΕ-27 (χάσμα με την Ελλάδα "&FIXED(Ανάλυση!F9,1,TRUE())&" μ.π.). Θέση ΔΜ: "&IF(Ανάλυση!F11=1,"η υψηλότερη των 13","η "&Ανάλυση!F11&"η υψηλότερη των 13")&" περιφερειών." -> Το 2025 η ανεργία στη ΔΜ ήταν 15,3% έναντι 8,9% στην Ελλάδα και 6,0% στην ΕΕ-27 (χάσμα με την Ελλάδα 6,4 μ.π.). Θέση ΔΜ: η υψηλότερη των 13 περιφερειών. | C5: =Ανάλυση!F9 -> 6.4 | D5: Ανάλυση §1
A6: 1.2 | B6: ="Από το 2021 η ΔΜ άλλαξε κατά "&FIXED(Ανάλυση!G6,1,TRUE())&" μ.π. και η Ελλάδα κατά "&FIXED(Ανάλυση!G7,1,TRUE())&" μ.π. Το χάσμα ΔΜ–Ελλάδα είναι "&FIXED(Ανάλυση!F9,1,TRUE())&" μ.π. το 2025 (2021: "&FIXED(Ανάλυση!B9,1,TRUE())&"· 2024: "&FIXED(Ανάλυση!E9,1,TRUE())&"). Η μεταβολή "&IF(Ανάλυση!G9>0,"+","")&FIXED(Ανάλυση!G9,1,TRUE())&" μ.π. "&IF(ABS(Ανάλυση!G9)>Ανάλυση!B62,"ξεπερνά","δεν ξεπερνά")&" το όριο θορύβου των "&FIXED(Ανάλυση!B62,1,TRUE())&" μ.π. (κανόνας 4.2)· "&IF(ABS(Ανάλυση!G9)>Ανάλυση!B62,"θεωρείται πραγματική μεταβολή.","το χάσμα θεωρείται μόνιμα υψηλό και όχι αποδεδειγμένα διευρυνόμενο.") -> Από το 2021 η ΔΜ άλλαξε κατά -4,5 μ.π. και η Ελλάδα κατά -5,8 μ.π. Το χάσμα ΔΜ–Ελλάδα είναι 6,4 μ.π. το 2025 (2021: 5,1· 2024: 2,4). Η μεταβολή +1,3 μ.π. δεν ξεπερνά το όριο θορύβου των 3,9 μ.π. (κανόνας 4.2)· το χάσμα θεωρείται μόνιμα υψηλό και όχι αποδεδειγμένα διευρυνόμενο. | C6: =Ανάλυση!G9 -> 1.3 | D6: Ανάλυση §1
A7: 1.3 | B7: ="Β΄ 2026: ανεργία ΔΜ "&FIXED(Δεδομένα!F88,1,TRUE())&"% έναντι "&FIXED(Δεδομένα!F95,1,TRUE())&"% στη χώρα· θέση ΔΜ "&IF(Ανάλυση!E36=1,"η υψηλότερη των 13","η "&Ανάλυση!E36&"η υψηλότερη των 13")&" περιφερειών." -> Β΄ 2026: ανεργία ΔΜ 12,7% έναντι 7,9% στη χώρα· θέση ΔΜ η 2η υψηλότερη των 13 περιφερειών. | C7: =Ανάλυση!E36 -> 2 | D7: Ανάλυση §3
A8: 1.4 | B8: ="Το τριμηνιαίο ποσοστό της ΔΜ κυμάνθηκε από "&FIXED(Ανάλυση!B76,1,TRUE())&"% έως "&FIXED(Ανάλυση!B77,1,TRUE())&"% ("&Ανάλυση!B78&" διαθέσιμα τρίμηνα 2022–"&Δεδομένα!B78&"). Γι’ αυτό οι συγκρίσεις γίνονται με ετήσια στοιχεία." -> Το τριμηνιαίο ποσοστό της ΔΜ κυμάνθηκε από 10,7% έως 19,5% (12 διαθέσιμα τρίμηνα 2022–Β΄ 2026). Γι’ αυτό οι συγκρίσεις γίνονται με ετήσια στοιχεία. | C8: =Ανάλυση!B77 -> 19.5 | D8: Δεδομένα Ε
A9: 2 · ΓΙΑΤΙ έγινε | B9: Δέντρο: ανεργία ← απασχόληση και συμμετοχή
A10: 2.1 | B10: ="Η απασχόληση (20–64) στη ΔΜ ήταν "&FIXED(Ανάλυση!C16,1,TRUE())&"% το 2025 έναντι "&FIXED(Ανάλυση!F16,1,TRUE())&"% στην Ελλάδα (χάσμα "&FIXED(Ανάλυση!I16,1,TRUE())&" μ.π.): "&IF(Ανάλυση!K16=1,"η χαμηλότερη των 13 περιφερειών.","η "&Ανάλυση!K16&"η χαμηλότερη των 13.") -> Η απασχόληση (20–64) στη ΔΜ ήταν 61,6% το 2025 έναντι 71,0% στην Ελλάδα (χάσμα -9,4 μ.π.): η χαμηλότερη των 13 περιφερειών. | C10: =Ανάλυση!I16 -> -9.4 | D10: Ανάλυση §2
A11: 2.2 | B11: ="Από το 2021 η απασχόληση ΔΜ άλλαξε κατά "&FIXED(Ανάλυση!D16,1,TRUE())&" μ.π. και της Ελλάδας κατά "&FIXED(Ανάλυση!G16,1,TRUE())&" μ.π.· το χάσμα απασχόλησης "&IF(Ανάλυση!I16<Ανάλυση!H16,"διευρύνθηκε","μειώθηκε")&" από "&FIXED(Ανάλυση!H16,1,TRUE())&" σε "&FIXED(Ανάλυση!I16,1,TRUE())&" μ.π. (συμμετοχή 15–64: από "&FIXED(Ανάλυση!H17,1,TRUE())&" σε "&FIXED(Ανάλυση!I17,1,TRUE())&" μ.π.)." -> Από το 2021 η απασχόληση ΔΜ άλλαξε κατά 3,4 μ.π. και της Ελλάδας κατά 8,4 μ.π.· το χάσμα απασχόλησης διευρύνθηκε από -4,4 σε -9,4 μ.π. (συμμετοχή 15–64: από -2,1 σε -4,3 μ.π.). | C11: =Ανάλυση!J16 -> -5 | D11: Ανάλυση §2
A12: 2.3 | B12: ="Β΄ 2026: η απασχόληση ανά πληθυσμό 15+ στη ΔΜ υστερεί της χώρας κατά "&FIXED(ABS(Ανάλυση!B39),1,TRUE())&" μ.π.· λογιστικά, περίπου "&ROUND(Ανάλυση!B42*100,0)&"% της διαφοράς αντιστοιχεί στη χαμηλότερη συμμετοχή στην αγορά εργασίας και "&ROUND(Ανάλυση!B43*100,0)&"% στην υψηλότερη ανεργία (διάσπαση, όχι αιτιώδης εξήγηση). Η συμμετοχή 15+ επηρεάζεται από τη σύνθεση ηλικιών." -> Β΄ 2026: η απασχόληση ανά πληθυσμό 15+ στη ΔΜ υστερεί της χώρας κατά 8,3 μ.π.· λογιστικά, περίπου 73% της διαφοράς αντιστοιχεί στη χαμηλότερη συμμετοχή στην αγορά εργασίας και 27% στην υψηλότερη ανεργία (διάσπαση, όχι αιτιώδης εξήγηση). Η συμμετοχή 15+ επηρεάζεται από τη σύνθεση ηλικιών. | C12: =Ανάλυση!B42 -> 0.72692205 | D12: Ανάλυση §3
A13: 2.4 | B13: ="Γυναίκες: ανεργία ΔΜ "&FIXED(Ανάλυση!C71,1,TRUE())&"% έναντι "&FIXED(Ανάλυση!C72,1,TRUE())&"% στους άνδρες (2025). Το χάσμα με την Ελλάδα για τις γυναίκες πήγε από "&FIXED(Ανάλυση!F71,1,TRUE())&" σε "&FIXED(Ανάλυση!G71,1,TRUE())&" μ.π., για τους άνδρες από "&FIXED(Ανάλυση!F72,1,TRUE())&" σε "&FIXED(Ανάλυση!G72,1,TRUE())&" μ.π. (βλ. 3.3 για την ευαισθησία στο έτος εκκίνησης)." -> Γυναίκες: ανεργία ΔΜ 21,2% έναντι 10,8% στους άνδρες (2025). Το χάσμα με την Ελλάδα για τις γυναίκες πήγε από 5,2 σε 10,0 μ.π., για τους άνδρες από 5,0 σε 3,8 μ.π. (βλ. 3.3 για την ευαισθησία στο έτος εκκίνησης). | C13: =Ανάλυση!H71 -> 4.8 | D13: Ανάλυση §5
A14: 3 · ΤΙ ΣΗΜΑΙΝΕΙ | B14: Ερμηνεία, μόνο όσο στηρίζεται στα δεδομένα
A15: 3.1 | B15: ="Η ανεργία από μόνη της υποτιμά το πρόβλημα: στο Β΄ 2026 η ΔΜ είναι "&IF(Ανάλυση!D36=1,"τελευταία","η "&Ανάλυση!D36&"η χειρότερη")&" στη συμμετοχή και "&IF(Ανάλυση!F36=1,"τελευταία","η "&Ανάλυση!F36&"η χειρότερη")&" στην απασχόληση ανά πληθυσμό, ενώ στην ανεργία είναι "&Ανάλυση!E36&"η." -> Η ανεργία από μόνη της υποτιμά το πρόβλημα: στο Β΄ 2026 η ΔΜ είναι τελευταία στη συμμετοχή και τελευταία στην απασχόληση ανά πληθυσμό, ενώ στην ανεργία είναι 2η. | C15: =Ανάλυση!F36 -> 1 | D15: Ανάλυση §3
A16: 3.2 | B16: ="Οι ετήσιες μεταβολές είναι θορυβώδεις: ΔΜ 2024 "&FIXED(Ανάλυση!B64,1,TRUE())&" μ.π. (σε απόλυτη τιμή μεγαλύτερη από το "&ROUND(Ανάλυση!B66*100,0)&"% των μεταβολών των περιφερειών) και 2025 "&IF(Ανάλυση!B65>0,"+","")&FIXED(Ανάλυση!B65,1,TRUE())&" μ.π. (μεγαλύτερη από το "&ROUND(Ανάλυση!B67*100,0)&"%). Κρίνουμε με την τάση 2021→2025, όχι με μεμονωμένα έτη." -> Οι ετήσιες μεταβολές είναι θορυβώδεις: ΔΜ 2024 -4,2 μ.π. (σε απόλυτη τιμή μεγαλύτερη από το 90% των μεταβολών των περιφερειών) και 2025 +2,8 μ.π. (μεγαλύτερη από το 63%). Κρίνουμε με την τάση 2021→2025, όχι με μεμονωμένα έτη. | C16: =Ανάλυση!B62 -> 3.89 | D16: Ανάλυση §4
A17: 3.3 | B17: ="Η ανεργία των γυναικών στη ΔΜ είναι "&IF(SUMPRODUCT(--(Δεδομένα!C60:G60>Δεδομένα!C61:G61))=5,"υψηλότερη από των ανδρών σε κάθε έτος 2021–2025","υψηλότερη από των ανδρών όχι σε όλα τα έτη")&". Το χάσμα των γυναικών με την Ελλάδα ήταν "&FIXED(Δεδομένα!C60-Δεδομένα!C62,1,TRUE())&" μ.π. (2021), "&FIXED(Δεδομένα!D60-Δεδομένα!D62,1,TRUE())&" (2022), "&FIXED(Δεδομένα!E60-Δεδομένα!E62,1,TRUE())&" (2023), "&FIXED(Δεδομένα!F60-Δεδομένα!F62,1,TRUE())&" (2024) και "&FIXED(Δεδομένα!G60-Δεδομένα!G62,1,TRUE())&" (2025): η μεταβολή "&IF(Ανάλυση!H71>0,"+","")&FIXED(Ανάλυση!H71,1,TRUE())&" μ.π. εξαρτάται από το έτος εκκίνησης και τα δείγματα ανά φύλο είναι μικρά· στους άνδρες η μεταβολή είναι "&IF(Ανάλυση!H72>0,"+","")&FIXED(Ανάλυση!H72,1,TRUE())&" μ.π. Ενδεικτικό εύρημα, όχι τεκμηριωμένη τάση." -> Η ανεργία των γυναικών στη ΔΜ είναι υψηλότερη από των ανδρών σε κάθε έτος 2021–2025. Το χάσμα των γυναικών με την Ελλάδα ήταν 5,2 μ.π. (2021), 8,0 (2022), 7,3 (2023), 6,2 (2024) και 10,0 (2025): η μεταβολή +4,8 μ.π. εξαρτάται από το έτος εκκίνησης και τα δείγματα ανά φύλο είναι μικρά· στους άνδρες η μεταβολή είναι -1,2 μ.π. Ενδεικτικό εύρημα, όχι τεκμηριωμένη τάση. | C17: =Ανάλυση!H71 -> 4.8 | D17: Ανάλυση §5
A18: 3.4 | B18: ="Ο πληθυσμός της ΔΜ άλλαξε κατά "&FIXED(Ανάλυση!B79,1,TRUE())&"% μεταξύ των Απογραφών 2011 και 2021. Τα δεδομένα δεν δείχνουν αν και πώς αυτό σχετίζεται με την ανεργία." -> Ο πληθυσμός της ΔΜ άλλαξε κατά -10,3% μεταξύ των Απογραφών 2011 και 2021. Τα δεδομένα δεν δείχνουν αν και πώς αυτό σχετίζεται με την ανεργία. | C18: =Ανάλυση!B79 -> -10.255597 | D18: Δεδομένα Ζ
A19: 3.5 | B19: ="Το 2025 η ανεργία αυξήθηκε σε "&COUNTIF(Ανάλυση!E48:E60,">0")&" από τις 13 περιφέρειες και μειώθηκε στις "&COUNTIF(Ανάλυση!E48:E60,"<0")&" υπόλοιπες· στη ΔΜ αυξήθηκε κατά "&FIXED(Ανάλυση!E54,1,TRUE())&" μ.π."&IF(Ανάλυση!E54=MAX(Ανάλυση!E48:E60)," (η μεγαλύτερη αύξηση)","")&". Σε απόλυτη τιμή η μεταβολή αυτή υπερβαίνει το "&ROUND(Ανάλυση!B67*100,0)&"% των "&COUNT(Ανάλυση!G48:J60)&" ετήσιων μεταβολών όλων των περιφερειών 2022–2025"&IF(ABS(Ανάλυση!E54)>Ανάλυση!B62,".",", αλλά δεν ξεπερνά το όριο των "&FIXED(Ανάλυση!B62,1,TRUE())&" μ.π. του κανόνα 4.2· ενδεικτική, όχι από μόνη της πραγματική αλλαγή.") -> Το 2025 η ανεργία αυξήθηκε σε 2 από τις 13 περιφέρειες και μειώθηκε στις 11 υπόλοιπες· στη ΔΜ αυξήθηκε κατά 2,8 μ.π. (η μεγαλύτερη αύξηση). Σε απόλυτη τιμή η μεταβολή αυτή υπερβαίνει το 63% των 52 ετήσιων μεταβολών όλων των περιφερειών 2022–2025, αλλά δεν ξεπερνά το όριο των 3,9 μ.π. του κανόνα 4.2· ενδεικτική, όχι από μόνη της πραγματική αλλαγή. | C19: =Ανάλυση!E54 -> 2.8 | D19: Ανάλυση §4
A20: 4 · ΤΙ ΚΑΝΟΥΜΕ ΤΩΡΑ | B20: Επόμενα βήματα: μέτρηση και πρόταση πιλοτικού, όχι προβλέψεις
A21: 4.1 | B21: ="Κύριος δείκτης: ποσοστό απασχόλησης 20–64 (βάση 2025: "&FIXED(Ανάλυση!C16,1,TRUE())&"%, χάσμα με Ελλάδα "&FIXED(Ανάλυση!I16,1,TRUE())&" μ.π.) και όχι μόνο η ανεργία. Πηγές: Eurostat (ετήσια), ΕΛΣΤΑΤ (τριμηνιαία)." -> Κύριος δείκτης: ποσοστό απασχόλησης 20–64 (βάση 2025: 61,6%, χάσμα με Ελλάδα -9,4 μ.π.) και όχι μόνο η ανεργία. Πηγές: Eurostat (ετήσια), ΕΛΣΤΑΤ (τριμηνιαία). | C21: =Ανάλυση!C16 -> 61.6 | D21: Ανάλυση §2
A22: 4.2 | B22: ="Κανόνας ανάγνωσης (ευρετικός, ορισμένος από τον συντάκτη): μια μεταβολή θεωρείται πραγματική μόνο αν ξεπερνά "&FIXED(Ανάλυση!B62,1,TRUE())&" μ.π. (90ο εκατοστημόριο των ετήσιων μεταβολών της συνολικής ανεργίας των περιφερειών· μέσος όρος |μεταβολής| "&FIXED(Ανάλυση!B63,1,TRUE())&" μ.π.) ή επαναλαμβάνεται δύο συνεχόμενα έτη. Για σειρές ανά φύλο ο θόρυβος είναι μεγαλύτερος." -> Κανόνας ανάγνωσης (ευρετικός, ορισμένος από τον συντάκτη): μια μεταβολή θεωρείται πραγματική μόνο αν ξεπερνά 3,9 μ.π. (90ο εκατοστημόριο των ετήσιων μεταβολών της συνολικής ανεργίας των περιφερειών· μέσος όρος |μεταβολής| 2,2 μ.π.) ή επαναλαμβάνεται δύο συνεχόμενα έτη. Για σειρές ανά φύλο ο θόρυβος είναι μεγαλύτερος. | C22: =Ανάλυση!B62 -> 3.89 | D22: Ανάλυση §4
A23: 4.3 | B23: ="Γυναίκες: πρώτη ομάδα για ανάλυση (ανεργία "&FIXED(Ανάλυση!C71,1,TRUE())&"% έναντι "&FIXED(Ανάλυση!C72,1,TRUE())&"% στους άνδρες). Πρόταση πιλοτικού στο φύλλο «Πιλοτικό_Πρόγραμμα», υπό την προϋπόθεση ότι θα ζητηθούν πρώτα από ΕΛΣΤΑΤ/Eurostat στοιχεία ΔΜ ανά φύλο και ηλικία/εκπαίδευση." -> Γυναίκες: πρώτη ομάδα για ανάλυση (ανεργία 21,2% έναντι 10,8% στους άνδρες). Πρόταση πιλοτικού στο φύλλο «Πιλοτικό_Πρόγραμμα», υπό την προϋπόθεση ότι θα ζητηθούν πρώτα από ΕΛΣΤΑΤ/Eurostat στοιχεία ΔΜ ανά φύλο και ηλικία/εκπαίδευση. | C23: =Ανάλυση!C71 -> 21.2 | D23: Ανάλυση §5
A24: 4.4 | B24: Πριν από επένδυση, συγκεντρώστε τρία στοιχεία που λείπουν: (α) κενές θέσεις και απασχόληση ανά κλάδο στη ΔΜ, (β) αποτελέσματα προηγούμενων προγραμμάτων ΔΥΠΑ στη ΔΜ, (γ) συμμετοχή ανά ηλικία. Χωρίς αυτά δεν προτείνεται κόστος ή αριθμός θέσεων. | C24: — | D24: Πηγές_Όρια
A26: Όρια και πηγές: φύλλο «Πηγές_Όρια». Δεν περιλαμβάνεται μοντέλο κόστους-οφέλους, επειδή απαιτούσε παραδοχές που δεν τεκμηριώνονται από δεδομένα.

Sheet Γραφήματα
A1: Γραφήματα · Δυτική Μακεδονία
A2: Τα γραφήματα διαβάζουν απευθείας τα φύλλα «Ανάλυση» και «Δεδομένα»· ενημερώνονται αυτόματα.

Sheet Δεδομένα
A1: Δεδομένα · ανεργία, απασχόληση, συμμετοχή
A2: Πηγές, ημερομηνίες άντλησης και όρια: βλ. φύλλο «Πηγές_Όρια».
A4: Α. Ανεργία 15–74 (%) · Eurostat, ετήσια
A5: Κωδικός | B5: Περιφέρεια | C5: 2021 | D5: 2022 | E5: 2023 | F5: 2024 | G5: 2025
A6: EL30 | B6: Αττική | C6: 11.9 | D6: 10 | E6: 9.4 | F6: 9.1 | G6: 8.1
A7: EL41 | B7: Βόρειο Αιγαίο | C7: 13.9 | D7: 11.5 | E7: 10 | F7: 7.1 | G7: 6.4
A8: EL42 | B8: Νότιο Αιγαίο | C8: 18.8 | D8: 10.7 | E8: 7.1 | F8: 9.9 | G8: 7.3
A9: EL43 | B9: Κρήτη | C9: 16.3 | D9: 12.1 | E9: 10.8 | F9: 8.6 | G9: 5.1
A10: EL51 | B10: Ανατ. Μακεδονία-Θράκη | C10: 18.5 | D10: 14.7 | E10: 12.1 | F10: 11.6 | G10: 10.6
A11: EL52 | B11: Κεντρική Μακεδονία | C11: 16.1 | D11: 14.7 | E11: 14.1 | F11: 12.8 | G11: 11.7
A12: EL53 | B12: Δυτική Μακεδονία | C12: 19.8 | D12: 17.7 | E12: 16.7 | F12: 12.5 | G12: 15.3
A13: EL54 | B13: Ήπειρος | C13: 15.1 | D13: 13.3 | E13: 13.8 | F13: 10.7 | G13: 9.9
A14: EL61 | B14: Θεσσαλία | C14: 16.7 | D14: 16.4 | E14: 12.9 | F14: 10 | G14: 6.3
A15: EL62 | B15: Ιόνια Νησιά | C15: 13.2 | D15: 12.9 | E15: 14.7 | F15: 16.2 | G15: 9
A16: EL63 | B16: Δυτική Ελλάδα | C16: 17.5 | D16: 12.6 | E16: 9.8 | F16: 10.1 | G16: 9.7
... A20: EU27_2020 | B20: ΕΕ-27 | C20: 7.1 | D20: 6.2 | E20: 6.1 | F20: 5.9 | G20: 6
A22: Β. Ποσοστό απασχόλησης 20–64 (%) · Eurostat, ετήσια
A23: Κωδικός | B23: Περιφέρεια | C23: 2021 | D23: 2022 | E23: 2023 | F23: 2024 | G23: 2025
A24: EL30 | B24: Αττική | C24: 65.7 | D24: 69.3 | E24: 69 | F24: 71 | G24: 73.1
A25: EL41 | B25: Βόρειο Αιγαίο | C25: 64 | D25: 67.3 | E25: 69.2 | F25: 70.7 | G25: 70
A26: EL42 | B26: Νότιο Αιγαίο | C26: 58.6 | D26: 64.4 | E26: 66.6 | F26: 69.1 | G26: 69.4
A27: EL43 | B27: Κρήτη | C27: 63.1 | D27: 68.8 | E27: 69.4 | F27: 71.4 | G27: 75.4
A28: EL51 | B28: Ανατ. Μακεδονία-Θράκη | C28: 59.5 | D28: 62.8 | E28: 66 | F28: 67.5 | G28: 67.6
A29: EL52 | B29: Κεντρική Μακεδονία | C29: 59.4 | D29: 63.6 | E29: 65.6 | F29: 68 | G29: 69.1
A30: EL53 | B30: Δυτική Μακεδονία | C30: 58.2 | D30: 58.8 | E30: 62.3 | F30: 64.8 | G30: 61.6
A31: EL54 | B31: Ήπειρος | C31: 55.8 | D31: 63.5 | E31: 65.3 | F31: 67.8 | G31: 69
A32: EL61 | B32: Θεσσαλία | C32: 62 | D32: 64.8 | E32: 63.7 | F32: 64.6 | G32: 69.4
A33: EL62 | B33: Ιόνια Νησιά | C33: 61.5 | D33: 64 | E33: 65.3 | F33: 67.2 | G33: 68.7
A34: EL63 | B34: Δυτική Ελλάδα | C34: 59.7 | D34: 62.4 | E34: 65.9 | F34: 66.8 | G34: 66.6
... A38: EU27_2020 | B38: ΕΕ-27 | C38: 73.1 | D38: 74.6 | E38: 75.3 | F38: 75.8 | G38: 76.1
A40: Γ. Ποσοστό συμμετοχής 15–64 (%) · Eurostat, ετήσια
A41: Κωδικός | B41: Περιφέρεια | C41: 2021 | D41: 2022 | E41: 2023 | F41: 2024 | G41: 2025
A42: EL30 | B42: Αττική | C42: 69 | D42: 71.1 | E42: 70.6 | F42: 71.9 | G42: 73.5
A43: EL41 | B43: Βόρειο Αιγαίο | C43: 68.6 | D43: 68.9 | E43: 69.9 | F43: 69.1 | G43: 68.6
A44: EL42 | B44: Νότιο Αιγαίο | C44: 66.2 | D44: 66.2 | E44: 65.6 | F44: 70.2 | G44: 67.7
A45: EL43 | B45: Κρήτη | C45: 68 | D45: 70.7 | E45: 70.7 | F45: 71.3 | G45: 72
A46: EL51 | B46: Ανατ. Μακεδονία-Θράκη | C46: 66.4 | D46: 67.2 | E46: 67.9 | F46: 68.7 | G46: 67.7
A47: EL52 | B47: Κεντρική Μακεδονία | C47: 64.4 | D47: 67.8 | E47: 69.5 | F47: 71.1 | G47: 70.7
A48: EL53 | B48: Δυτική Μακεδονία | C48: 65.2 | D48: 63.7 | E48: 66.9 | F48: 67.1 | G48: 66.6
A49: EL54 | B49: Ήπειρος | C49: 59.9 | D49: 67.3 | E49: 70.1 | F49: 69.4 | G49: 69.9
...

Sheet Ανάλυση
A1: Ανάλυση · όλα τα νούμερα είναι τύποι πάνω στο φύλλο «Δεδομένα»
A2: Θέση 1 = χειρότερη τιμή μεταξύ των 13 περιφερειών. μ.π. = ποσοστιαίες μονάδες.
A4: 1 · ΤΙ: ανεργία 15–74 (%) και χάσμα
A5: Μέγεθος | B5: 2021 | C5: 2022 | D5: 2023 | E5: 2024 | F5: 2025 | G5: Μεταβολή 2021→2025
A6: Δυτική Μακεδονία | B6: =Δεδομένα!C12 -> 19.8 | C6: =Δεδομένα!D12 -> 17.7 | D6: =Δεδομένα!E12 -> 16.7 | E6: =Δεδομένα!F12 -> 12.5 | F6: =Δεδομένα!G12 -> 15.3 | G6: =F6-B6 -> -4.5
A7: Ελλάδα | B7: =Δεδομένα!C19 -> 14.7 | C7: =Δεδομένα!D19 -> 12.5 | D7: =Δεδομένα!E19 -> 11.1 | E7: =Δεδομένα!F19 -> 10.1 | F7: =Δεδομένα!G19 -> 8.9 | G7: =F7-B7 -> -5.8
A8: ΕΕ-27 | B8: =Δεδομένα!C20 -> 7.1 | C8: =Δεδομένα!D20 -> 6.2 | D8: =Δεδομένα!E20 -> 6.1 | E8: =Δεδομένα!F20 -> 5.9 | F8: =Δεδομένα!G20 -> 6 | G8: =F8-B8 -> -1.1
A9: Χάσμα ΔΜ–Ελλάδα (μ.π.) | B9: =B6-B7 -> 5.1 | C9: =C6-C7 -> 5.2 | D9: =D6-D7 -> 5.6 | E9: =E6-E7 -> 2.4 | F9: =F6-F7 -> 6.4 | G9: =F9-B9 -> 1.3
A10: Χάσμα ΔΜ–ΕΕ-27 (μ.π.) | B10: =B6-B8 -> 12.7 | C10: =C6-C8 -> 11.5 | D10: =D6-D8 -> 10.6 | E10: =E6-E8 -> 6.6 | F10: =F6-F8 -> 9.3 | G10: =F10-B10 -> -3.4
A11: Θέση ΔΜ από 13 (1 = υψηλότερη ανεργία) | B11: =COUNTIF(Δεδομένα!C$6:C$18,">"&B6)+1 -> 1 | C11: =COUNTIF(Δεδομένα!D$6:D$18,">"&C6)+1 -> 1 | D11: =COUNTIF(Δεδομένα!E$6:E$18,">"&D6)+1 -> 1 | E11: =COUNTIF(Δεδομένα!F$6:F$18,">"&E6)+1 -> 3 | F11: =COUNTIF(Δεδομένα!G$6:G$18,">"&F6)+1 -> 1 | G11: —
A13: 2 · ΓΙΑΤΙ (δέντρο): ανεργία ← απασχόληση και συμμετοχή
A14: Δείκτης | B14: ΔΜ 2021 | C14: ΔΜ 2025 | D14: Μεταβ. ΔΜ | E14: Ελλάδα 2021 | F14: Ελλάδα 2025 | G14: Μεταβ. Ελλάδας | H14: Χάσμα 2021 | I14: Χάσμα 2025 | J14: Μεταβ. χάσματος | K14: Θέση ΔΜ 2025 (1 = χειρότερη)
A15: Ανεργία 15–74 (%) | B15: =Δεδομένα!C12 -> 19.8 | C15: =Δεδομένα!G12 -> 15.3 | D15: =C15-B15 -> -4.5 | E15: =Δεδομένα!C19 -> 14.7 | F15: =Δεδομένα!G19 -> 8.9 | G15: =F15-E15 -> -5.8 | H15: =B15-E15 -> 5.1 | I15: =C15-F15 -> 6.4 | J15: =I15-H15 -> 1.3 | K15: =COUNTIF(Δεδομένα!G$6:G$18,">"&C15)+1 -> 1
A16: Απασχόληση 20–64 (%) | B16: =Δεδομένα!C30 -> 58.2 | C16: =Δεδομένα!G30 -> 61.6 | D16: =C16-B16 -> 3.4 | E16: =Δεδομένα!C37 -> 62.6 | F16: =Δεδομένα!G37 -> 71 | G16: =F16-E16 -> 8.4 | H16: =B16-E16 -> -4.4 | I16: =C16-F16 -> -9.4 | J16: =I16-H16 -> -5 | K16: =COUNTIF(Δεδομένα!G$24:G$36,"<"&C16)+1 -> 1
A17: Συμμετοχή 15–64 (%) | B17: =Δεδομένα!C48 -> 65.2 | C17: =Δεδομένα!G48 -> 66.6 | D17: =C17-B17 -> 1.4 | E17: =Δεδομένα!C55 -> 67.3 | F17: =Δεδομένα!G55 -> 70.9 | G17: =F17-E17 -> 3.6 | H17: =B17-E17 -> -2.1 | I17: =C17-F17 -> -4.3 | J17: =I17-H17 -> -2.2 | K17: =COUNTIF(Δεδομένα!G$42:G$54,"<"&C17)+1 -> 3
A18: Προσοχή: διαφορετικές βάσεις ηλικίας (20–64 έναντι 15–64) → η σύγκριση απασχόλησης/συμμετοχής είναι ενδεικτική.
A20: 3 · ΓΙΑΤΙ (ακριβής διάσπαση): Β΄ 2026, ΕΛΣΤΑΤ, πληθυσμός 15+
A21: Περιφέρεια | B21: Εργατικό δυναμικό (χιλ.) | C21: Πληθυσμός 15+ (χιλ.) | D21: Συμμετοχή % | E21: Ανεργία % | F21: Απασχόληση / πληθυσμό %
A22: =Δεδομένα!B82 -> Αττική | B22: =Δεδομένα!C82+Δεδομένα!D82 -> 1753.5 | C22: =B22+Δεδομένα!E82 -> 3173.9 | D22: =B22/C22*100 -> 55.247487 | E22: =Δεδομένα!D82/B22*100 -> 6.5982321 | F22: =Δεδομένα!C82/C22*100 -> 51.60213
A23: =Δεδομένα!B83 -> Βόρειο Αιγαίο | B23: =Δεδομένα!C83+Δεδομένα!D83 -> 84.2 | C23: =B23+Δεδομένα!E83 -> 164.6 | D23: =B23/C23*100 -> 51.154313 | E23: =Δεδομένα!D83/B23*100 -> 5.3444181 | F23: =Δεδομένα!C83/C23*100 -> 48.420413
A24: =Δεδομένα!B84 -> Νότιο Αιγαίο | B24: =Δεδομένα!C84+Δεδομένα!D84 -> 148.1 | C24: =B24+Δεδομένα!E84 -> 268.6 | D24: =B24/C24*100 -> 55.137751 | E24: =Δεδομένα!D84/B24*100 -> 7.0898042 | F24: =Δεδομένα!C84/C24*100 -> 51.228593
A25: =Δεδομένα!B85 -> Κρήτη | B25: =Δεδομένα!C85+Δεδομένα!D85 -> 297.5 | C25: =B25+Δεδομένα!E85 -> 511.2 | D25: =B25/C25*100 -> 58.196401 | E25: =Δεδομένα!D85/B25*100 -> 4.5042017 | F25: =Δεδομένα!C85/C25*100 -> 55.575117
A26: =Δεδομένα!B86 -> Ανατ. Μακεδονία-Θράκη | B26: =Δεδομένα!C86+Δεδομένα!D86 -> 248.6 | C26: =B26+Δεδομένα!E86 -> 502.8 | D26: =B26/C26*100 -> 49.443119 | E26: =Δεδομένα!D86/B26*100 -> 8.2864039 | F26: =Δεδομένα!C86/C26*100 -> 45.346062
A27: =Δεδομένα!B87 -> Κεντρική Μακεδονία | B27: =Δεδομένα!C87+Δεδομένα!D87 -> 834.5 | C27: =B27+Δεδομένα!E87 -> 1573.4 | D27: =B27/C27*100 -> 53.038007 | E27: =Δεδομένα!D87/B27*100 -> 9.4068304 | F27: =Δεδομένα!C87/C27*100 -> 48.048811
A28: =Δεδομένα!B88 -> Δυτική Μακεδονία | B28: =Δεδομένα!C88+Δεδομένα!D88 -> 108 | C28: =B28+Δεδομένα!E88 -> 230.8 | D28: =B28/C28*100 -> 46.793761 | E28: =Δεδομένα!D88/B28*100 -> 12.777778 | F28: =Δεδομένα!C88/C28*100 -> 40.814558
A29: =Δεδομένα!B89 -> Ήπειρος | B29: =Δεδομένα!C89+Δεδομένα!D89 -> 141.2 | C29: =B29+Δεδομένα!E89 -> 288.3 | D29: =B29/C29*100 -> 48.97676 | E29: =Δεδομένα!D89/B29*100 -> 10.552408 | F29: =Δεδομένα!C89/C29*100 -> 43.808533
A30: =Δεδομένα!B90 -> Θεσσαλία | B30: =Δεδομένα!C90+Δεδομένα!D90 -> 306.5 | C30: =B30+Δεδομένα!E90 -> 611.9 | D30: =B30/C30*100 -> 50.089884 | E30: =Δεδομένα!D90/B30*100 -> 8.1892333 | F30: =Δεδομένα!C90/C30*100 -> 45.987907
A31: =Δεδομένα!B91 -> Ιόνια Νησιά | B31: =Δεδομένα!C91+Δεδομένα!D91 -> 95.7 | C31: =B31+Δεδομένα!E91 -> 168.8 | D31: =B31/C31*100 -> 56.694313 | E31: =Δεδομένα!D91/B31*100 -> 13.375131 | F31: =Δεδομένα!C91/C31*100 -> 49.111374
A32: =Δεδομένα!B92 -> Δυτική Ελλάδα | B32: =Δεδομένα!C92+Δεδομένα!D92 -> 286 | C32: =B32+Δεδομένα!E92 -> 561.9 | D32: =B32/C32*100 -> 50.898736 | E32: =Δεδομένα!D92/B32*100 -> 12.447552 | F32: =Δεδομένα!C92/C32*100 -> 44.56309
A33: =Δεδομένα!B93 -> Στερεά Ελλάδα | B33: =Δεδομένα!C93+Δεδομένα!D93 -> 241.1 | C33: =B33+Δεδομένα!E93 -> 466.1 | D33: =B33/C33*100 -> 51.727097 | E33: =Δεδομένα!D93/B33*100 -> 6.2629614 | F33: =Δεδομένα!C93/C33*100 -> 48.487449
... A35: =Δεδομένα!B95 -> ΣΥΝΟΛΟ ΧΩΡΑΣ | B35: =Δεδομένα!C95+Δεδομένα!D95 -> 4794.1 | C35: =B35+Δεδομένα!E95 -> 8983.6 | D35: =B35/C35*100 -> 53.365021 | E35: =Δεδομένα!D95/B35*100 -> 7.9201519 | F35: =Δεδομένα!C95/C35*100 -> 49.13843
A36: Θέση ΔΜ από 13 (1 = χειρότερη) | D36: =COUNTIF(D22:D34,"<"&D28)+1 -> 1 | E36: =COUNTIF(E22:E34,">"&E28)+1 -> 2 | F36: =COUNTIF(F22:F34,"<"&F28)+1 -> 1
A37: Οι ρυθμοί υπολογίζονται από πλήθη σε χιλιάδες, άρα μπορεί να διαφέρουν κατά 0,1 μ.π. από τους δημοσιευμένους.
A39: Διαφορά απασχόλησης/πληθυσμό ΔΜ–Ελλάδα (μ.π.) | B39: =F28-F35 -> -8.323872
A40: … από χαμηλότερη συμμετοχή | B40: =(D28-D35)*(1-E35/100) -> -6.0508061
A41: … από υψηλότερη ανεργία | B41: =D28*(E35-E28)/100 -> -2.2730659
A42: Μερίδιο συμμετοχής | B42: =B40/B39 -> 0.72692205
A43: Μερίδιο ανεργίας | B43: =B41/B39 -> 0.27307795
A44: Έλεγχος: άθροισμα − διαφορά (πρέπει 0) | B44: =ROUND(B40+B41-B39,6) -> 0
A46: 4 · ΘΟΡΥΒΟΣ: ετήσιες μεταβολές ανεργίας των 13 περιφερειών (μ.π.)
...

Sheet Πηγές_Όρια
A1: Πηγές, κατάσταση επαλήθευσης και όρια
A3: Σύνολο δεδομένων | B3: Πηγή / κωδικός | C3: Χρήση | D3: Ημερ. άντλησης | E3: Κατάσταση επαλήθευσης
A4: Ανεργία 15–74 ανά NUTS2, ετήσια | B4: Eurostat · tgs00010 (κωδικός επιβεβαιωμένος στο ευρετήριο Eurostat στις 22/10/2026· ηλικία 15–74) | C4: Δεδομένα Α | D4: Άγνωστη· δεν καταγράφεται στο αρχικό σύνολο δεδομένων. | E4: Μη επανεξαχθέν. Διασταυρωμένα με δημοσιεύσεις: ΔΜ 2025 και 2024, μεταβολές 2021→2022 στο Νότιο Αιγαίο και τη Δυτική Ελλάδα, Ελλάδα 2024–2025, ΕΕ-27 2024–2025 (βλ. παρακάτω).
A5: Ποσοστό απασχόλησης 20–64 ανά NUTS2 | B5: Eurostat · lfst_r_lfe2emprt (κωδικός επιβεβαιωμένος στο ευρετήριο Eurostat στις 22/10/2026) | C5: Δεδομένα Β | D5: Άγνωστη· δεν καταγράφεται στο αρχικό σύνολο δεδομένων. | E5: Μη επανεξαχθέν – χρησιμοποιήθηκαν οι τιμές του αρχικού συνόλου δεδομένων. Δεν έγινε έλεγχος με πρωτογενή πηγή.
A6: Ποσοστό συμμετοχής 15–64 ανά NUTS2 | B6: Eurostat · lfst_r_lfp2actrt (κωδικός βρέθηκε στο ευρετήριο Eurostat στις 22/10/2026) | C6: Δεδομένα Γ | D6: Άγνωστη· δεν καταγράφεται στο αρχικό σύνολο δεδομένων. | E6: Μη επανεξαχθέν – χρησιμοποιήθηκαν οι τιμές του αρχικού συνόλου δεδομένων. Δεν έγινε έλεγχος με πρωτογενή πηγή.
A7: Ανεργία ανά φύλο, ΔΜ και Ελλάδα | B7: Eurostat · lfst_r_lfu3rt (κωδικός επιβεβαιωμένος στις 22/10/2026· διαστάσεις: φύλο, ηλικία) | C7: Δεδομένα Δ | D7: 16/10/2026 (δηλώνεται στο αρχικό σύνολο δεδομένων) | E7: Μη επανεξαχθέν. Εσωτερικά συνεπές με τα συνολικά ποσοστά (βλ. παρακάτω).
A8: Τριμηνιαία ανεργία ΔΜ και Ελλάδας | B8: ΕΛΣΤΑΤ, Έρευνα Εργατικού Δυναμικού (δελτία τύπου) | C8: Δεδομένα Ε | D8: 18/10/2026 | E8: Ελλάδα: διασταυρωμένο με δελτία ΕΛΣΤΑΤ (Α΄ 2022–Δ΄ 2025). ΔΜ: Δ΄ 2024 διασταυρωμένο· η τιμή Β΄ 2025 (14,3%) δεν έχει επαληθευτεί.
A9: Β΄ 2026 ανά περιφέρεια (πλήθη, ποσοστά) | B9: ΕΛΣΤΑΤ, δελτίο Έρευνας Εργατικού Δυναμικού Β΄ 2026 | C9: Δεδομένα ΣΤ | D9: Δελτίο 4/9/2026· αντλήθηκε 18/10/2026 | E9: Επαληθευμένο από τον συντάκτη (πλήρες PDF δελτίου). Πλήθη σε χιλιάδες.
A10: Πληθυσμός ΔΜ, Απογραφές 2011 και 2021 | B10: ΕΛΣΤΑΤ, Απογραφή 2021, οριστικά αποτελέσματα (17/3/2023, όπως δημοσιεύθηκαν από την ΕΕΤΑΑ) | C10: Δεδομένα Ζ | D10: 22/10/2026 | E10: Επαληθευμένο: οριστικά αποτελέσματα ΕΛΣΤΑΤ, 2011 = 283.689 και 2021 = 254.595.
A12: Όρια της ανάλυσης
A13: 1. Η Έρευνα Εργατικού Δυναμικού έχει μικρό δείγμα σε επίπεδο περιφέρειας· τα τριμηνιαία και ετήσια ποσοστά της ΔΜ διακυμαίνονται έντονα (Ανάλυση §4, §6). Το όριο 3,9 μ.π. προέρχεται από τη συνολική ανεργία των περιφερειών· για σειρές ανά φύλο και για χάσματα (διαφορές δύο θορυβωδών σειρών) ο θόρυβος είναι μεγαλύτερος.
A14: 2. Δεν υπάρχουν στοιχεία ΔΜ ανά ηλικία, εκπαίδευση ή κλάδο στα δεδομένα· τα ευρήματα δείχνουν «τι» και «πόσο», όχι τις αιτίες σε επίπεδο κλάδων.
A15: 3. Η συμμετοχή 15+ επηρεάζεται από τη σύνθεση ηλικιών (π.χ. γήρανση)· η διάσπαση του §3 δεν την αποσυνδέει.
A16: 4. Η απασχόληση (20–64) και η συμμετοχή (15–64) έχουν διαφορετική βάση ηλικίας· η σύγκρισή τους (§2) είναι ενδεικτική.
A17: 5. Δεν περιλαμβάνεται μοντέλο κόστους-οφέλους ή πρόβλεψη θέσεων εργασίας, επειδή θα στηριζόταν σε παραδοχές χωρίς δημοσιευμένη τεκμηρίωση.
A19: Διασταύρωση με επίσημες δημοσιεύσεις
A20: Eurostat, Regions in Europe 2026: η ανεργία της ΔΜ το 2025 είναι 15,3%.
A21: Eurostat (lfst_r_lfu3rt), Statistics Explained: οι μεταβολές 2021→2022 στο Νότιο Αιγαίο (−8,1 μ.π.) και στη Δυτική Ελλάδα (−4,9 μ.π.) συμφωνούν με το αρχείο.
A22: Eurobank Research (12/3/2025), βάσει ΕΛΣΤΑΤ: ΔΜ 2024 = 12,5% (−4,2 μ.π.) και Ελλάδα 2024 = 10,1%.
A23: Δελτία Eurostat: ΕΕ-27 ανεργία 2024 = 5,9% και 2025 = 6,0%· ΕΕ-27 απασχόληση 20–64 2024 = 75,8% και 2025 = 76,1%· Ελλάδα ανεργία 2025 = 8,9%· Ελλάδα απασχόληση 2024 = 69,3% και 2025 = 71,0%.
A24: Δελτία ΕΛΣΤΑΤ: οι 10 τιμές ανεργίας της Ελλάδας από Α΄ 2022 έως Δ΄ 2025 και η τιμή της ΔΜ για το Δ΄ 2024 (10,7%) συμφωνούν με τα δελτία.
... A28: Δεν έχουν διασταυρωθεί με πρωτογενή πηγή: οι περιφερειακές τιμές των συνόλων Α, Β, Γ και Δ που δεν αναφέρονται παραπάνω, οι τριμηνιαίες τιμές της ΔΜ εκτός του Δ΄ 2024, και η τιμή της ΔΜ για το Β΄ 2025 (14,3%).

Sheet Πιλοτικό_Πρόγραμμα
A1: Προτεινόμενο πιλοτικό πρόγραμμα απασχόλησης · Δυτική Μακεδονία
A2: Τίτλος | B2: Τοπική Παρέμβαση Επανένταξης στην Αγορά Εργασίας – Δυτική Μακεδονία.
A3: Τύπος | B3: Πιλοτικό πρόγραμμα 12 μηνών.
A4: Στόχος | B4: Βελτίωση της πρόσβασης των άνεργων γυναικών της Δυτικής Μακεδονίας στην τοπική αγορά εργασίας και αύξηση της απασχόλησης. Επέκταση σε άλλες ομάδες μόνο μετά από στοιχεία ΔΜ ανά ηλικία και εκπαίδευση.
A5: Τεκμηρίωση | B5: ="Το 2025 η ανεργία στη Δυτική Μακεδονία ήταν "&FIXED(Ανάλυση!F6,1,TRUE())&"% έναντι "&FIXED(Ανάλυση!F7,1,TRUE())&"% στην Ελλάδα. Η απασχόληση 20–64 ήταν "&FIXED(Ανάλυση!C16,1,TRUE())&"% έναντι "&FIXED(Ανάλυση!F16,1,TRUE())&"%. Η ανεργία των γυναικών ήταν "&FIXED(Ανάλυση!C71,1,TRUE())&"% έναντι "&FIXED(Ανάλυση!C72,1,TRUE())&"% των ανδρών." -> Το 2025 η ανεργία στη Δυτική Μακεδονία ήταν 15,3% έναντι 8,9% στην Ελλάδα. Η απασχόληση 20–64 ήταν 61,6% έναντι 71,0%. Η ανεργία των γυναικών ήταν 21,2% έναντι 10,8% των ανδρών.
A6: Ωφελούμενοι | B6: Άνεργες γυναίκες ΔΜ: η μόνη ομάδα που στηρίζεται από τα διαθέσιμα δεδομένα (ανεργία ανά φύλο). Νέοι άνεργοι, μακροχρόνια άνεργοι και άνεργοι με χαμηλές ψηφιακές δεξιότητες δεν μπορούν να τεκμηριωθούν με τα σημερινά στοιχεία.
A7: Δράσεις | B7: Συμβουλευτική και καταγραφή δεξιοτήτων· κατάρτιση σε ψηφιακές δεξιότητες· σύνδεση με τοπικές επιχειρήσεις· επιδοτούμενη πρακτική άσκηση ή απασχόληση 6–12 μηνών· παρακολούθηση για 6 μήνες μετά την ολοκλήρωση.
A8: Διάρκεια | B8: 12 μήνες υλοποίηση και 6 μήνες παρακολούθηση αποτελεσμάτων.
A9: Δείκτες | B9: Ποσοστό ολοκλήρωσης κατάρτισης, ποσοστό έναρξης πρακτικής/απασχόλησης, ποσοστό απασχολημένων μετά 6 μήνες, μεταβολή απασχόλησης 20–64 και διαφορά ανεργίας ανδρών-γυναικών.
A10: Δεδομένα τώρα | B10: Ετήσια ανεργία, απασχόληση, συμμετοχή, ανεργία ανά φύλο και τριμηνιαία στοιχεία Eurostat/ΕΛΣΤΑΤ, ήδη στο αρχείο.
A11: Δεδομένα αργότερα | B11: Κενές θέσεις ανά κλάδο, αποτελέσματα προηγούμενων προγραμμάτων ΔΥΠΑ, συμμετοχή ανά ηλικία και εκπαίδευση, μακροχρόνια ανεργία. Απαραίτητα πριν από κλιμάκωση ή επέκταση σε άλλες ομάδες.
A12: Περιορισμός | B12: Δεν προτείνονται κόστος, αριθμός θέσεων ή πρόβλεψη μείωσης ανεργίας χωρίς τεκμηριωμένα στοιχεία τοπικής ζήτησης εργασίας.
A13: Αξιολόγηση | B13: Σύγκριση πριν/μετά με ομάδα ελέγχου (difference-in-differences) μόνο αν υπάρξουν δεδομένα ωφελούμενων και ομάδας ελέγχου. Δεν εκτιμάται κανένα μοντέλο σε αυτό το αρχείο.
